2024-08-27T09:45:52.126145+0000 ERROR An error has been caught in function '<module>', process 'MainProcess' (1), thread 'MainThread' (140526412458880):
Traceback (most recent call last):

  File "/usr/local/lib/python3.10/site-packages/pdf2image/pdf2image.py", line 581, in pdfinfo_from_path
    proc = Popen(command, env=env, stdout=PIPE, stderr=PIPE)
           │     │            │           │            └ -1
           │     │            │           └ -1
           │     │            └ {'PATH': '/usr/local/bin:/usr/local/sbin:/usr/local/bin:/usr/sbin:/usr/bin:/sbin:/bin', 'HOSTNAME': 'a9253b588c15', 'TERM': '...
           │     └ ['C:\\Users\\wertiba\\Documents\\Install\\Release-24.07.0-0\\poppler-24.07.0\\Library\\bin/pdfinfo', '/app/test_pdf.pdf']
           └ <class 'subprocess.Popen'>
  File "/usr/local/lib/python3.10/subprocess.py", line 971, in __init__
    self._execute_child(args, executable, preexec_fn, close_fds,
    │    │              │     │           │           └ True
    │    │              │     │           └ None
    │    │              │     └ None
    │    │              └ ['C:\\Users\\wertiba\\Documents\\Install\\Release-24.07.0-0\\poppler-24.07.0\\Library\\bin/pdfinfo', '/app/test_pdf.pdf']
    │    └ <function Popen._execute_child at 0x7fcec678e3b0>
    └ <Popen: returncode: 255 args: ['C:\\Users\\wertiba\\Documents\\Install\\Rele...>
  File "/usr/local/lib/python3.10/subprocess.py", line 1863, in _execute_child
    raise child_exception_type(errno_num, err_msg, err_filename)
          │                    │          │        └ 'C:\\Users\\wertiba\\Documents\\Install\\Release-24.07.0-0\\poppler-24.07.0\\Library\\bin/pdfinfo'
          │                    │          └ 'No such file or directory'
          │                    └ 2
          └ <class 'OSError'>

FileNotFoundError: [Errno 2] No such file or directory: 'C:\\Users\\wertiba\\Documents\\Install\\Release-24.07.0-0\\poppler-24.07.0\\Library\\bin/pdfinfo'


During handling of the above exception, another exception occurred:


Traceback (most recent call last):

> File "/app/main.py", line 134, in <module>
    main()
    └ <function main at 0x7fcebcaa8b80>

  File "/app/main.py", line 130, in main
    extract_and_process_images_in_memory(pdf_path)
    │                                    └ '/app/test_pdf.pdf'
    └ <function extract_and_process_images_in_memory at 0x7fcebcaa8820>

  File "/app/main.py", line 97, in extract_and_process_images_in_memory
    pages = convert_from_path(pdf_path, poppler_path=poppler_path)
            │                 │                      └ 'C:\\Users\\wertiba\\Documents\\Install\\Release-24.07.0-0\\poppler-24.07.0\\Library\\bin'
            │                 └ '/app/test_pdf.pdf'
            └ <function convert_from_path at 0x7fcebd9e16c0>

  File "/usr/local/lib/python3.10/site-packages/pdf2image/pdf2image.py", line 127, in convert_from_path
    page_count = pdfinfo_from_path(
                 └ <function pdfinfo_from_path at 0x7fcebd339990>
  File "/usr/local/lib/python3.10/site-packages/pdf2image/pdf2image.py", line 607, in pdfinfo_from_path
    raise PDFInfoNotInstalledError(
          └ <class 'pdf2image.exceptions.PDFInfoNotInstalledError'>

pdf2image.exceptions.PDFInfoNotInstalledError: Unable to get page count. Is poppler installed and in PATH?
2024-08-27T09:58:06.564591+0000 ERROR An error has been caught in function '<module>', process 'MainProcess' (1), thread 'MainThread' (139951501273984):
Traceback (most recent call last):

> File "/app/main.py", line 134, in <module>
    main()
    └ <function main at 0x7f48e14b4c10>

  File "/app/main.py", line 129, in main
    pdf_path = clean_word(str(input('Copy the full path to the PDF document: ')), symbols_to_remove='\"')
               └ <function clean_word at 0x7f48e14b4790>

EOFError: EOF when reading a line
2024-08-27T10:03:37.748230+0000 INFO page 1
2024-08-27T10:03:37.764734+0000 INFO the image has been converted to the required format
2024-08-27T10:03:38.111903+0000 ERROR An error has been caught in function '<module>', process 'MainProcess' (1), thread 'MainThread' (140503228578688):
Traceback (most recent call last):

> File "/app/main.py", line 114, in <module>
    main()
    └ <function main at 0x7fc956cdcb80>

  File "/app/main.py", line 110, in main
    extract_and_process_images_in_memory(pdf_path)
    │                                    └ '/app/test_pdf.pdf'
    └ <function extract_and_process_images_in_memory at 0x7fc956cdc820>

  File "/app/main.py", line 89, in extract_and_process_images_in_memory
    image_with_rect = refactor(page_cv)
                      │        └ array([[[255, 255, 255],
                      │                  [255, 255, 255],
                      │                  [255, 255, 255],
                      │                  ...,
                      │                  [255, 255, 255],
                      │                  [255...
                      └ <function refactor at 0x7fc956cdc790>

  File "/app/main.py", line 33, in refactor
    text = pytesseract.image_to_string(img, config=config, lang='rus')
           │           │               │           └ '--oem 3 --psm 6'
           │           │               └ array([[[255, 255, 255],
           │           │                         [255, 255, 255],
           │           │                         [255, 255, 255],
           │           │                         ...,
           │           │                         [255, 255, 255],
           │           │                         [255...
           │           └ <function image_to_string at 0x7fc957bdd090>
           └ <module 'pytesseract' from '/usr/local/lib/python3.10/site-packages/pytesseract/__init__.py'>

  File "/usr/local/lib/python3.10/site-packages/pytesseract/pytesseract.py", line 486, in image_to_string
    return {
  File "/usr/local/lib/python3.10/site-packages/pytesseract/pytesseract.py", line 489, in <lambda>
    Output.STRING: lambda: run_and_get_output(*args),
    │      │               │                   └ [array([[[255, 255, 255],
    │      │               │                             [255, 255, 255],
    │      │               │                             [255, 255, 255],
    │      │               │                             ...,
    │      │               │                             [255, 255, 255],
    │      │               │                             [25...
    │      │               └ <function run_and_get_output at 0x7fc957bdcc10>
    │      └ 'string'
    └ <class 'pytesseract.pytesseract.Output'>
  File "/usr/local/lib/python3.10/site-packages/pytesseract/pytesseract.py", line 352, in run_and_get_output
    run_tesseract(**kwargs)
    │               └ {'input_filename': '/tmp/tess_cajqkko1_input.PNG', 'output_filename_base': '/tmp/tess_cajqkko1', 'extension': 'txt', 'lang': ...
    └ <function run_tesseract at 0x7fc957bdca60>
  File "/usr/local/lib/python3.10/site-packages/pytesseract/pytesseract.py", line 284, in run_tesseract
    raise TesseractError(proc.returncode, get_errors(error_string))
          │              │    │           │          └ b'Error opening data file /usr/share/tesseract-ocr/rus.traineddata\nPlease make sure the TESSDATA_PREFIX environment variable...
          │              │    │           └ <function get_errors at 0x7fc957bdc700>
          │              │    └ 1
          │              └ <Popen: returncode: 1 args: ['tesseract', '/tmp/tess_cajqkko1_input.PNG', '/...>
          └ <class 'pytesseract.pytesseract.TesseractError'>

pytesseract.pytesseract.TesseractError: (1, 'Error opening data file /usr/share/tesseract-ocr/rus.traineddata Please make sure the TESSDATA_PREFIX environment variable is set to your "tessdata" directory. Failed loading language \'rus\' Tesseract couldn\'t load any languages! Could not initialize tesseract.')
2024-08-27T11:17:44.192081+0000 INFO page 1
2024-08-27T11:17:44.228618+0000 INFO the image has been converted to the required format
2024-08-27T11:17:44.675271+0000 ERROR An error has been caught in function '<module>', process 'MainProcess' (1), thread 'MainThread' (140070066391936):
Traceback (most recent call last):

> File "/app/main.py", line 114, in <module>
    main()
    └ <function main at 0x7f647c558b80>

  File "/app/main.py", line 110, in main
    extract_and_process_images_in_memory(pdf_path)
    │                                    └ '/app/test_pdf.pdf'
    └ <function extract_and_process_images_in_memory at 0x7f647c558820>

  File "/app/main.py", line 89, in extract_and_process_images_in_memory
    image_with_rect = refactor(page_cv)
                      │        └ array([[[255, 255, 255],
                      │                  [255, 255, 255],
                      │                  [255, 255, 255],
                      │                  ...,
                      │                  [255, 255, 255],
                      │                  [255...
                      └ <function refactor at 0x7f647c558790>

  File "/app/main.py", line 33, in refactor
    text = pytesseract.image_to_string(img, config=config, lang='rus')
           │           │               │           └ '--oem 3 --psm 6'
           │           │               └ array([[[255, 255, 255],
           │           │                         [255, 255, 255],
           │           │                         [255, 255, 255],
           │           │                         ...,
           │           │                         [255, 255, 255],
           │           │                         [255...
           │           └ <function image_to_string at 0x7f647d3e9090>
           └ <module 'pytesseract' from '/usr/local/lib/python3.10/site-packages/pytesseract/__init__.py'>

  File "/usr/local/lib/python3.10/site-packages/pytesseract/pytesseract.py", line 486, in image_to_string
    return {
  File "/usr/local/lib/python3.10/site-packages/pytesseract/pytesseract.py", line 489, in <lambda>
    Output.STRING: lambda: run_and_get_output(*args),
    │      │               │                   └ [array([[[255, 255, 255],
    │      │               │                             [255, 255, 255],
    │      │               │                             [255, 255, 255],
    │      │               │                             ...,
    │      │               │                             [255, 255, 255],
    │      │               │                             [25...
    │      │               └ <function run_and_get_output at 0x7f647d3e8c10>
    │      └ 'string'
    └ <class 'pytesseract.pytesseract.Output'>
  File "/usr/local/lib/python3.10/site-packages/pytesseract/pytesseract.py", line 352, in run_and_get_output
    run_tesseract(**kwargs)
    │               └ {'input_filename': '/tmp/tess_f8150els_input.PNG', 'output_filename_base': '/tmp/tess_f8150els', 'extension': 'txt', 'lang': ...
    └ <function run_tesseract at 0x7f647d3e8a60>
  File "/usr/local/lib/python3.10/site-packages/pytesseract/pytesseract.py", line 284, in run_tesseract
    raise TesseractError(proc.returncode, get_errors(error_string))
          │              │    │           │          └ b'Error opening data file /usr/share/tesseract-ocr/4.00/tessdata/rus.traineddata\nPlease make sure the TESSDATA_PREFIX enviro...
          │              │    │           └ <function get_errors at 0x7f647d3e8700>
          │              │    └ 1
          │              └ <Popen: returncode: 1 args: ['tesseract', '/tmp/tess_f8150els_input.PNG', '/...>
          └ <class 'pytesseract.pytesseract.TesseractError'>

pytesseract.pytesseract.TesseractError: (1, 'Error opening data file /usr/share/tesseract-ocr/4.00/tessdata/rus.traineddata Please make sure the TESSDATA_PREFIX environment variable is set to your "tessdata" directory. Failed loading language \'rus\' Tesseract couldn\'t load any languages! Could not initialize tesseract.')
